Workbook

Sheet Impostazioni
A1: Piano Mezza Maratona d'Italia 2027 – Impostazioni
A2: Modifica solo le celle gialle (menu a tendina). Le date nel foglio Workouts si aggiornano da sole.
A4: Nuoto – giorno 1 | B4: Martedì
A5: Nuoto – giorno 2 | B5: Giovedì
A6: Giorno del lungo | B6: Sabato
A7: Inizio piano (lunedì settimana 1) | B7: 46300 | C7: Fisso: la settimana 23 finisce con la gara
A8: Gara (domenica, fissa) | B8: 46460
A10: Calcoli (non modificare)
C11: n. nuoto 1 | D11: =MATCH(B4,Regole!$H$2:$H$8,0)-1 -> 1
C12: n. nuoto 2 | D12: =MATCH(B5,Regole!$H$2:$H$8,0)-1 -> 3
C13: n. lungo | D13: =MATCH(B6,Regole!$H$2:$H$8,0)-1 -> 5
C14: chiave | D14: =MIN(D11,D12)&"-"&MAX(D11,D12)&"-"&D13 -> 1-3-5
C15: chiave gara | D15: =MIN(D11,D12)&"-"&MAX(D11,D12)&"-6" -> 1-3-6
E16: Facile | F16: Qualità | G16: Lungo
A17: Offset settimana normale | E17: =IFERROR(INDEX(Regole!$A$2:$D$43,MATCH($D$14,Regole!$A$2:$A$43,0),2),0) -> 0 | F17: =IFERROR(INDEX(Regole!$A$2:$D$43,MATCH($D$14,Regole!$A$2:$A$43,0),3),2) -> 2 | G17: =IFERROR(INDEX(Regole!$A$2:$D$43,MATCH($D$14,Regole!$A$2:$A$43,0),4),5) -> 5
A18: Offset settimana gara | E18: =IFERROR(INDEX(Regole!$A$2:$D$43,MATCH($D$15,Regole!$A$2:$A$43,0),2),0) -> 4 | F18: =IFERROR(INDEX(Regole!$A$2:$D$43,MATCH($D$15,Regole!$A$2:$A$43,0),3),2) -> 2 | G18: =IFERROR(INDEX(Regole!$A$2:$D$43,MATCH($D$15,Regole!$A$2:$A$43,0),4),6) -> 6
A20: Risultato
A21: Corsa facile | B21: =INDEX(Regole!$H$2:$H$8,E17+1) -> Lunedì
A22: Seduta di qualità | B22: =INDEX(Regole!$H$2:$H$8,F17+1) -> Mercoledì
A23: Lungo | B23: =INDEX(Regole!$H$2:$H$8,G17+1) -> Sabato
A24: Controllo | B24: =IF(D11=D12,"ATTENZIONE: i due giorni di nuoto devono essere diversi",IF(OR(D11=D13,D12=D13),"Nota: il lungo cade in un giorno di nuoto (nuota leggero o dopo la corsa)",IF(IFERROR(INDEX(Regole!$E$2:$E$43,MATCH(D14,Regole!$A$2:$A$43,0)),"")<>"","Compromesso inevitabile: "&INDEX(Regole!$E$2:$E$43,MATCH(D14,Regole!$A$2:$A$43,0)),"OK: corse ben distanziate"))) -> OK: corse ben distanziate
A26: Settimana tipo
B27: Lunedì | C27: Martedì | D27: Mercoledì | E27: Giovedì | F27: Venerdì | G27: Sabato | H27: Domenica
A28: Attività | B28: =IF(OR(0=$D$11,0=$D$12),"Nuoto","")&IF(AND(OR(0=$D$11,0=$D$12),OR(0=$E$17,0=$F$17,0=$G$17))," + ","")&IF(0=$E$17,"Facile",IF(0=$F$17,"Qualità",IF(0=$G$17,"Lungo",""))) -> Facile | C28: =IF(OR(1=$D$11,1=$D$12),"Nuoto","")&IF(AND(OR(1=$D$11,1=$D$12),OR(1=$E$17,1=$F$17,1=$G$17))," + ","")&IF(1=$E$17,"Facile",IF(1=$F$17,"Qualità",IF(1=$G$17,"Lungo",""))) -> Nuoto | D28: =IF(OR(2=$D$11,2=$D$12),"Nuoto","")&IF(AND(OR(2=$D$11,2=$D$12),OR(2=$E$17,2=$F$17,2=$G$17))," + ","")&IF(2=$E$17,"Facile",IF(2=$F$17,"Qualità",IF(2=$G$17,"Lungo",""))) -> Qualità | E28: =IF(OR(3=$D$11,3=$D$12),"Nuoto","")&IF(AND(OR(3=$D$11,3=$D$12),OR(3=$E$17,3=$F$17,3=$G$17))," + ","")&IF(3=$E$17,"Facile",IF(3=$F$17,"Qualità",IF(3=$G$17,"Lungo",""))) -> Nuoto | F28: =IF(OR(4=$D$11,4=$D$12),"Nuoto","")&IF(AND(OR(4=$D$11,4=$D$12),OR(4=$E$17,4=$F$17,4=$G$17))," + ","")&IF(4=$E$17,"Facile",IF(4=$F$17,"Qualità",IF(4=$G$17,"Lungo",""))) | G28: =IF(OR(5=$D$11,5=$D$12),"Nuoto","")&IF(AND(OR(5=$D$11,5=$D$12),OR(5=$E$17,5=$F$17,5=$G$17))," + ","")&IF(5=$E$17,"Facile",IF(5=$F$17,"Qualità",IF(5=$G$17,"Lungo",""))) -> Lungo | H28: =IF(OR(6=$D$11,6=$D$12),"Nuoto","")&IF(AND(OR(6=$D$11,6=$D$12),OR(6=$E$17,6=$F$17,6=$G$17))," + ","")&IF(6=$E$17,"Facile",IF(6=$F$17,"Qualità",IF(6=$G$17,"Lungo","")))
B29: =IF(B28="","riposo","") | C29: =IF(C28="","riposo","") | D29: =IF(D28="","riposo","") | E29: =IF(E28="","riposo","") | F29: =IF(F28="","riposo","") -> riposo | G29: =IF(G28="","riposo","") | H29: =IF(H28="","riposo","") -> riposo
A31: Come si usa
A32: 1. Scegli i giorni nelle celle gialle e SALVA il file in Excel (così le date vengono memorizzate).
A33: 2. Carica il file in garminPlannerCGPT e usa Carica+Pianifica.
A34: 3. Il programma, quando salva, tiene solo Workouts, Parameters ed Esempi DSL: conserva una copia di questo file come originale.
A35: 4. Settimana 23: la gara resta domenica 14/03; facile e rifinitura vengono messe prima, lontane dal sabato.

Sheet Workouts
A1: Week | B1: Date | C1: Session | D1: Sport | E1: Description | F1: Steps | G1: WorkoutId | H1: WorkoutScheduleId | I1: ScheduledDate
A2: 1 | B2: =Impostazioni!$B$7+(A2-1)*7+IF(A2=23,INDEX(Impostazioni!$E$18:$G$18,C2),INDEX(Impostazioni!$E$17:$G$17,C2)) -> 46300 | C2: 1 | D2: Running | E2: Facile 35’ FC<145 | F2: interval: 35min @ HR_Z2
A3: 1 | B3: =Impostazioni!$B$7+(A3-1)*7+IF(A3=23,INDEX(Impostazioni!$E$18:$G$18,C3),INDEX(Impostazioni!$E$17:$G$17,C3)) -> 46302 | C3: 2 | D3: Running | E3: Facile 35’ FC<145 | F3: interval: 35min @ HR_Z2
A4: 1 | B4: =Impostazioni!$B$7+(A4-1)*7+IF(A4=23,INDEX(Impostazioni!$E$18:$G$18,C4),INDEX(Impostazioni!$E$17:$G$17,C4)) -> 46305 | C4: 3 | D4: Running | E4: Lungo 7 km FC<150 | F4: interval: 7km @ HR_Z3
A5: 2 | B5: =Impostazioni!$B$7+(A5-1)*7+IF(A5=23,INDEX(Impostazioni!$E$18:$G$18,C5),INDEX(Impostazioni!$E$17:$G$17,C5)) -> 46307 | C5: 1 | D5: Running | E5: Facile 35’ FC<145 + 4 allunghi | F5: interval: 35min @ HR_Z2 repeat 4: interval: 20sec recovery: 1min @ Z1
A6: 2 | B6: =Impostazioni!$B$7+(A6-1)*7+IF(A6=23,INDEX(Impostazioni!$E$18:$G$18,C6),INDEX(Impostazioni!$E$17:$G$17,C6)) -> 46309 | C6: 2 | D6: Running | E6: Facile 40’ FC<145 | F6: interval: 40min @ HR_Z2
A7: 2 | B7: =Impostazioni!$B$7+(A7-1)*7+IF(A7=23,INDEX(Impostazioni!$E$18:$G$18,C7),INDEX(Impostazioni!$E$17:$G$17,C7)) -> 46312 | C7: 3 | D7: Running | E7: Lungo 8 km FC<150 | F7: interval: 8km @ HR_Z3
A8: 3 | B8: =Impostazioni!$B$7+(A8-1)*7+IF(A8=23,INDEX(Impostazioni!$E$18:$G$18,C8),INDEX(Impostazioni!$E$17:$G$17,C8)) -> 46314 | C8: 1 | D8: Running | E8: Facile 40’ FC<145 + 4 allunghi | F8: interval: 40min @ HR_Z2 repeat 4: interval: 20sec recovery: 1min @ Z1
A9: 3 | B9: =Impostazioni!$B$7+(A9-1)*7+IF(A9=23,INDEX(Impostazioni!$E$18:$G$18,C9),INDEX(Impostazioni!$E$17:$G$17,C9)) -> 46316 | C9: 2 | D9: Running | E9: Fartlek 6×(1’ @5:05-5:15 + 2’ facile) | F9: warmup: 10min @ HR_Z2 repeat 6: interval: 1min @ threshold_range recovery: 2min @ Z2 cooldown: 10min @ HR_Z2
A10: 3 | B10: =Impostazioni!$B$7+(A10-1)*7+IF(A10=23,INDEX(Impostazioni!$E$18:$G$18,C10),INDEX(Impostazioni!$E$17:$G$17,C10)) -> 46319 | C10: 3 | D10: Running | E10: Lungo 9 km FC<150 | F10: interval: 9km @ HR_Z3
A11: 4 | B11: =Impostazioni!$B$7+(A11-1)*7+IF(A11=23,INDEX(Impostazioni!$E$18:$G$18,C11),INDEX(Impostazioni!$E$17:$G$17,C11)) -> 46321 | C11: 1 | D11: Running | E11: Facile 35’ FC<145 | F11: interval: 35min @ HR_Z2
A12: 4 | B12: =Impostazioni!$B$7+(A12-1)*7+IF(A12=23,INDEX(Impostazioni!$E$18:$G$18,C12),INDEX(Impostazioni!$E$17:$G$17,C12)) -> 46323 | C12: 2 | D12: Running | E12: Facile 35’ FC<145 + 6 allunghi | F12: interval: 35min @ HR_Z2 repeat 6: interval: 20sec recovery: 1min @ Z1
A13: 4 | B13: =Impostazioni!$B$7+(A13-1)*7+IF(A13=23,INDEX(Impostazioni!$E$18:$G$18,C13),INDEX(Impostazioni!$E$17:$G$17,C13)) -> 46326 | C13: 3 | D13: Running | E13: Lungo 8 km FC<150 | F13: interval: 8km @ HR_Z3
... A70: 23 | B70: =Impostazioni!$B$7+(A70-1)*7+IF(A70=23,INDEX(Impostazioni!$E$18:$G$18,C70),INDEX(Impostazioni!$E$17:$G$17,C70)) -> 46460 | C70: 3 | D70: Running | E70: GARA – Mezza Maratona d’Italia (obiettivo sub 2h) | F70: warmup: lap-button @ Z1 interval: 21.1km @ hmp

Sheet Parameters
A1: Key | B1: Metric | C1: Expression | D1: Notes
A2: Z1 | B2: pace | C2: 7:00-7:30 | D2: Zona 1: Recupero / defaticamento
A3: Z2 | B3: pace | C3: 6:35-7:00 | D3: Zona 2: Facile aerobico (riscaldamento)
A4: Z3 | B4: pace | C4: 5:30-5:40 | D4: Zona 3: Passo mezza (obiettivo sub 2h)
A5: Z4 | B5: pace | C5: 5:05-5:15 | D5: Zona 4: Soglia
A6: Z5 | B6: pace | C6: 4:50-5:00 | D6: Zona 5: VO2max / ripetute 800-1000 m
A7: easy_range | B7: pace | C7: 6:35-7:00 | D7: Corsa facile: lento DAVVERO
A8: long_range | B8: pace | C8: 6:20-6:45 | D8: Ritmo lungo
A9: hmp | B9: pace | C9: 5:30-5:40 | D9: Passo mezza maratona (5:35/km ≈ 1:58 sui 21,1 km)
A10: threshold_range | B10: pace | C10: 5:05-5:15 | D10: Ritmo soglia
A11: vo2 | B11: pace | C11: 4:50-5:00 | D11: Ritmo ripetute 800-1000 m
A12: fast | B12: pace | C12: 4:40-4:50 | D12: Ritmo ripetute 400 m
... A21: hr_tolerance | B21: hr | C21: 5 | D21: Tolleranza ±bpm per HR singoli

Sheet Esempi DSL
A1: Categoria | B1: Esempio | C1: Descrizione
A2: DURATE | B2: warmup: 10min @ Z2 | C2: Durata in minuti (anche: 10m, 10')
A3: DURATE | B3: interval: 30sec @ Z5 | C3: Durata in secondi (anche: 30s)
A4: DURATE | B4: warmup: lap-button @ Z2 | C4: Premi lap per continuare
A5: DISTANZE | B5: interval: 1000m @ 5:00 | C5: Distanza in metri
A6: DISTANZE | B6: interval: 5km @ Z3 | C6: Distanza in chilometri
A7: DISTANZE | B7: interval: 400m @ Z5 | C7: Distanze brevi per ripetute
A8: TARGET RITMO | B8: interval: 3km @ 5:00 | C8: Ritmo fisso min:sec/km (usa tolerance)
A9: TARGET RITMO | B9: interval: 3km @ 5:00-5:30 | C9: Range di ritmo esplicito
A10: TARGET RITMO | B10: interval: 3km @ Z3 | C10: Zona ritmo da Parameters
A11: TARGET RITMO | B11: interval: 5km @ marathon | C11: Ritmo custom da Parameters
A12: TARGET RITMO | B12: warmup: 10min @ easy_range | C12: Range custom da Parameters
... A34: NOTE | B34: HR_max: personalizza in Parameters per calcolare le zone FC automaticamente | C34: Le zone HR_Z1-HR_Z5 sono percentuali di HR_max

Sheet Regole
A1: Chiave (nuoto1-nuoto2-lungo) | B1: Facile | C1: Qualità | D1: Lungo | E1: Nota | G1: N | H1: Giorno
A2: 0-1-5 | B2: 6 | C2: 2 | D2: 5 | E2: due corse in giorni consecutivi | G2: 0 | H2: Lunedì
A3: 0-1-6 | B3: 4 | C3: 2 | D3: 6 | G3: 1 | H3: Martedì
A4: 0-2-5 | B4: 3 | C4: 1 | D4: 5 | G4: 2 | H4: Mercoledì
A5: 0-2-6 | B5: 1 | C5: 3 | D5: 6 | G5: 3 | H5: Giovedì
A6: 0-3-5 | B6: 6 | C6: 1 | D6: 5 | E6: due corse in giorni consecutivi | G6: 4 | H6: Venerdì
A7: 0-3-6 | B7: 4 | C7: 2 | D7: 6 | G7: 5 | H7: Sabato
A8: 0-4-5 | B8: 3 | C8: 1 | D8: 5 | G8: 6 | H8: Domenica
A9: 0-4-6 | B9: 1 | C9: 3 | D9: 6
A10: 0-5-5 | B10: 3 | C10: 1 | D10: 5
A11: 0-5-6 | B11: 1 | C11: 3 | D11: 6
A12: 0-6-5 | B12: 3 | C12: 1 | D12: 5
A13: 0-6-6 | B13: 1 | C13: 3 | D13: 6
A14: 1-2-5 | B14: 0 | C14: 3 | D14: 5
A15: 1-2-6 | B15: 0 | C15: 3 | D15: 6 | E15: due corse in giorni consecutivi
A16: 1-3-5 | B16: 0 | C16: 2 | D16: 5
A17: 1-3-6 | B17: 4 | C17: 2 | D17: 6
A18: 1-4-5 | B18: 0 | C18: 2 | D18: 5
A19: 1-4-6 | B19: 0 | C19: 2 | D19: 6 | E19: due corse in giorni consecutivi
A20: 1-5-5 | B20: 0 | C20: 2 | D20: 5
A21: 1-5-6 | B21: 4 | C21: 2 | D21: 6
A22: 1-6-5 | B22: 0 | C22: 2 | D22: 5
A23: 1-6-6 | B23: 4 | C23: 2 | D23: 6
A24: 2-3-5 | B24: 6 | C24: 1 | D24: 5 | E24: due corse in giorni consecutivi
A25: 2-3-6 | B25: 1 | C25: 4 | D25: 6
A26: 2-4-5 | B26: 3 | C26: 1 | D26: 5
A27: 2-4-6 | B27: 1 | C27: 3 | D27: 6
A28: 2-5-5 | B28: 3 | C28: 1 | D28: 5
A29: 2-5-6 | B29: 1 | C29: 3 | D29: 6
A30: 2-6-5 | B30: 3 | C30: 1 | D30: 5
A31: 2-6-6 | B31: 1 | C31: 3 | D31: 6
A32: 3-4-5 | B32: 0 | C32: 2 | D32: 5
A33: 3-4-6 | B33: 0 | C33: 2 | D33: 6 | E33: due corse in giorni consecutivi
A34: 3-5-5 | B34: 0 | C34: 2 | D34: 5
A35: 3-5-6 | B35: 4 | C35: 2 | D35: 6
A36: 3-6-5 | B36: 0 | C36: 2 | D36: 5
A37: 3-6-6 | B37: 4 | C37: 2 | D37: 6
A38: 4-5-5 | B38: 0 | C38: 2 | D38: 5
A39: 4-5-6 | B39: 1 | C39: 3 | D39: 6
A40: 4-6-5 | B40: 0 | C40: 2 | D40: 5
...
